Workbook

Sheet Original
A1: MONTHLY FIRE ALARM TESTING - NOVEMBER 2011 - OCTOBER 2012
A2: ADDRESS | B2: PROPERTY MANAGER | C2: TEST DAY | D2: ANNUAL | E2: 2011 NOV | F2: DEC | G2: 2012 JAN | H2: FEB | I2: MAR | J2: APR | K2: MAY | L2: JUN | M2: JLY | N2: AUG | O2: SEPT | P2: OCT
A3: 703 Broughton | B3: 486261 BC LTD | C3: W1 | D3: April | E3: 3 | F3: 3 | G3: 3 | H3: 3 | I3: 3 | J3: A | K3: 3 | L3: 3 | M3: 3 | N3: 3
A4: 1133A Reynolds | B4: Abbeyfield S. Peters | C4: W4 | D4: May | E4: 3 | F4: 3 | G4: 3 | H4: 3 | I4: 3 | J4: 3 | K4: A | L4: 3 | M4: 3
A5: 707 Courtney @ $112.50/mth | B5: AWM Alliance | C5: W1 | D5: Aug | E5: 3 | F5: 3 | G5: 3 | H5: 3 | I5: 3 | J5: 3 | K5: 3 | L5: A | M5: 3 | N5: 3
A6: 770 Fisgard | B6: AWM Alliance | C6: W2 | D6: Sept | E6: 3 | F6: 3 | G6: 3 | H6: 3 | I6: 3 | J6: 3 | K6: 3 | L6: 3 | M6: 3 | N6: 3 | O6: A
A7: 545 Manchester/520 Dunedin | B7: Baywood | C7: W2 | D7: May | E7: 3 | F7: 3 | G7: 3 | H7: NA | I7: 3 | J7: 3 | K7: X | L7: A | M7: 3 | N7: 3 | Q7: MBT- not done in May as annual moved to June 2012
A8: 120 Douglas | B8: Boorman | C8: T | D8: Jan | E8: 3 | F8: 3 | G8: A | H8: 3 | I8: 3 | J8: 3 | K8: 3 | L8: 3 | M8: 3 | N8: 3
A9: 945 McClure | B9: Boorman | C9: T | D9: Dec | E9: 3 | F9: A | G9: 3 | H9: 3 | I9: 3 | J9: 3 | K9: 3 | L9: 3 | M9: 3 | N9: 3
A10: 1436 Harrison | B10: Boormans | C10: T | D10: Feb | E10: 3 | F10: 3 | G10: 3 | H10: A | I10: 3 | J10: 3 | K10: 3 | L10: 3 | M10: 3 | N10: 3
A11: 515 Foul Bay | B11: Brian McLoughlin Inv.4229 pd to Oct/12 @ $40/mth | C11: W1 | D11: April | E11: NA | F11: NA | G11: NA | H11: 3 | I11: 3 | J11: 3 | K11: 3 | L11: 3 | M11: 3 | N11: 3
A12: 2020 Richmond | B12: Brown Bros | C12: W1 | D12: July | E12: 3 | F12: 3 | G12: 3 | H12: 3 | I12: 3 | J12: 3 | K12: 3 | L12: 3 | M12: A | N12: 3
A13: 605 Cook | B13: Brown Bros | C13: T | D13: Feb | E13: 3 | F13: 3 | G13: 3 | H13: A | I13: 3 | J13: 3 | K13: 3 | L13: 3 | M13: 3 | N13: 3
A14: 655 Herald | B14: Brown Bros | C14: W2 | D14: March | E14: 3 | F14: 3 | G14: 3 | H14: 3 | I14: A | J14: 3 | K14: 3 | L14: 3 | M14: 3 | N14: 3
A15: 55 Songhees | B15: Brown Bros | C15: W4 | D15: Jan | E15: 3 | F15: 3 | G15: A | H15: 3 | I15: 3 | J15: 3 | K15: 3 | L15: 3 | M15: 3
A16: 2626 Blackwood | B16: Brown Bros Inv. 4838 pd to Feb.29/12 @ $45/mth | C16: W4 | D16: April | E16: 3 | F16: 3 | G16: 3 | H16: 3 | I16: Cancelled
A17: 50 & 60 Bastion/ 1200 Government | B17: Colliers | C17: W2 | D17: Jan | E17: 3 | F17: 3 | G17: A | H17: 3 | I17: 3 | J17: 3 | K17: 3 | L17: 3 | M17: 3 | N17: 3
A18: 1000-1012 Douglas | B18: Colliers | C18: W1 | D18: Sept | E18: 3 | F18: 3 | G18: 3 | H18: 3 | I18: 3 | J18: 3 | K18: 3 | L18: 3 | M18: 3 | N18: 3 | O18: A
A19: 1005 Broad | B19: Colliers | C19: W1 | D19: Sept | E19: 3 | F19: 3 | G19: 3 | H19: 3 | I19: 3 | J19: 3 | K19: 3 | L19: 3 | M19: 3 | N19: 3 | O19: A
A20: 1205 Broad Street/650 View Street | B20: Newport | C20: W2 | D20: April | I20: 3 | J20: A | K20: 3 | L20: 3 | M20: 3 | N20: 3
A21: 1205 Broad Street/650 View Street | B21: Colliers | C21: W2 | D21: April | E21: 3 | F21: NA | G21: 3 | H21: 3 | I21: CANCELLED
A22: 1207 Douglas | B22: Colliers | C22: W1 | D22: May | E22: 3 | F22: 3 | G22: 3 | H22: 3 | I22: 3 | J22: 3 | K22: A | L22: 3 | M22: 3 | N22: 3
A23: 1581 Hillside | B23: Colliers | C23: T | D23: June | E23: 3 | F23: 3 | G23: 3 | H23: 3 | I23: 3 | J23: 3 | K23: 3 | L23: A | M23: 3 | N23: 3
A24: 230 Cook | B24: 230 Cook Street Holdings c/o Colliers | C24: T | D24: Oct | E24: 3 | F24: 3 | G24: 3 | H24: 3 | I24: 3 | J24: 3 | K24: 3 | L24: 3 | M24: 3 | N24: 3 | P24: A
A25: 2250 Oak Bay | B25: Colliers | C25: T | D25: Dec | E25: 3 | F25: A | G25: 3 | H25: 3 | I25: 3 | J25: 3 | K25: 3 | L25: 3 | M25: 3 | N25: 3
A26: 3045 Douglas Street | B26: Colliers | C26: W4 | D26: May | E26: 3 | F26: 3 | G26: 3 | H26: NA | I26: 3 | J26: 3 | K26: A | L26: 3 | M26: 3
A27: 3400 Davidson | B27: Colliers | C27: W4 | D27: March | E27: 3 | F27: 3 | G27: 3 | H27: 3 | I27: A | J27: 3 | K27: 3 | L27: 3 | M27: 3
A28: 609 Broughton | B28: Colliers | C28: W1 | D28: March | E28: 3 | F28: 3 | G28: 3 | H28: 3 | I28: A | J28: 3 | K28: 3 | L28: 3 | M28: 3 | N28: 3
A29: 721-725 Yates | B29: Colliers - Inv. 4888 Nov. 1/11 - Apr. 30/12 | C29: W1 | D29: May | E29: 3 | F29: 3 | G29: 3 | H29: 3 | I29: 3 | J29: 3 | K29: A | L29: 3 | M29: 3 | N29: 3
A30: 765-777 Broughton | B30: Colliers | C30: W1 | D30: Sept | E30: 3 | F30: 3 | G30: 3 | H30: 3 | I30: 3 | J30: 3 | K30: 3 | L30: 3 | M30: 3 | N30: 3 | O30: A
A31: 777 Fort | B31: Colliers | C31: W1 | D31: July | E31: 3 | F31: 3 | G31: 3 | H31: 3 | I31: 3 | J31: 3 | K31: 3 | L31: 3 | M31: A | N31: 3
A32: 825-827 Fort | B32: Colliers | C32: W1 | D32: May | E32: 3 | F32: 3 | G32: 3 | H32: 3 | I32: 3 | J32: 3 | K32: A | L32: 3 | M32: 3 | N32: 3
A33: 838 Fort | B33: Colliers | C33: W1 | D33: Aug | E33: 3 | F33: 3 | G33: 3 | H33: 3 | I33: 3 | J33: 3 | K33: 3 | L33: 3 | M33: A | N33: NA
A34: 914 Yates | B34: Colliers | C34: W2 | D34: Jan | E34: 3 | F34: 3 | G34: A | H34: 3 | I34: 3 | J34: 3 | K34: 3 | L34: 3 | M34: 3 | N34: 3
A35: 1223 Johnson | B35: Complete Res. | C35: W2 | D35: Jan | E35: 3 | F35: 3 | G35: A | H35: 3 | I35: 3 | J35: 3 | K35: 3 | L35: 3 | M35: 3 | N35: 3
A36: 1111 Hillside | B36: Complete Res. | C36: W4 | D36: Nov | E36: A | F36: 3 | G36: 3 | H36: 3 | I36: 3 | J36: 3 | K36: 3 | L36: 3 | M36: 3
A37: 845 Yates | B37: Cornerstone | C37: W2 | D37: Jan by Others | E37: 3 | F37: 3 | G37: A | H37: 3 | I37: 3 | J37: 3 | K37: 3 | L37: 3 | M37: 3 | N37: 3
A38: 710 Redbrick | B38: Gulf Pacific | C38: W4 | D38: March | E38: 3 | F38: NA | G38: 3 | H38: 3 | I38: A | J38: 3 | K38: 3 | L38: 3 | M38: 3
A39: 836 Yates | B39: Coronet Ventures | C39: W2 | D39: Mar | E39: 3 | F39: 3 | G39: 3 | H39: 3 | I39: A | J39: 3 | K39: 3 | L39: 3 | M39: 3 | N39: 3
A40: 708 View | B40: DVN Investments | C40: W2 | D40: Dec | E40: 3 | F40: A | G40: 3 | H40: 3 | I40: 3 | J40: 3 | K40: 3 | L40: 3 | M40: 3 | N40: 3
...

Sheet MBT - summary
A2: STATUS- (ACTIVE, CANCELLED, ON HOLD) | B2: (Multiple Items) | D2: TEST DAY | E2: T | G2: Apr-13 | H2: (All)
A4: Row Labels | B4: ANNUAL | C4: ADDRESS | D4: SITE NAME | E4: KEYS | F4: MONITORING | G4: PANEL | H4: MBT NOTES
A5: 1 | B5: January | C5: 625 Hillside | D5: n/a
D6: Pemberton Holmes | E6: Y 526 | F6: none | G6: Edwards 6616 | H6: (blank)
A7: 2 | B7: June | C7: 1581 Hillside | D7: n/a
D8: Colliers | E8: W 1851 | F8: M6 T A | G8: Edwards EST 6616 | H8: in room by McDonalds 24hr drive thru. Annunciator at 1581 lobby to 2nd floor
A9: 3 | B9: Oct | C9: 1560 Hillside | D9: n/a
D10: Hutton | E10: B 0561 | F10: none | G10: Edwards Custom 6500 | H10: Strata#1214 site contact Jerry 250-519-4728. Lock Power Rm door. Press reset button on Mag-Lock supply box. Aux disconnect.
A11: 4 | B11: March | C11: 1510 Hillside | D11: The Pearl
D12: Firm Management | E12: BT 0151 | F12: PRICES T A | G12: Mircom 1000 | H12: Entrance at left side of bldg. Elec. Rm off driveway. Signal silence LED may not illuminate but bells will stop.
A13: 5 | B13: May | C13: 1366 Hillside | D13: (blank)
D14: Gibraltar | E14: A 6631 | F14: (blank) | G14: (blank) | H14: (blank)
A15: 6 | B15: Oct | C15: 2151 Haultain | D15: (blank)
D16: Quadra Pacific | E16: C 1512 | F16: (blank) | G16: (blank) | H16: (blank)
A17: 7 | B17: Nov | C17: 2230 Cadboro Bay | D17: (blank)
D18: Quadra Pacific | E18: D 0322 | F18: (blank) | G18: (blank) | H18: (blank)
A19: 8 | B19: Dec | C19: 2250 Oak Bay | D19: (blank)
D20: Colliers | E20: E 0522 | F20: (blank) | G20: (blank) | H20: (blank)
A21: 9 | B21: March | C21: 2119 Oak Bay | D21: (blank)
D22: Hutton | E22: P 9112 | F22: (blank) | G22: (blank) | H22: (blank)
A23: 10 | B23: August | C23: 1975 Lee | D23: (blank)
D24: Hutton | E24: F 5791 | F24: (blank) | G24: (blank) | H24: (blank)
A25: 11 | B25: May | C25: 1655 Begbie | D25: (blank)
D26: Proline | E26: G 5561 | F26: (blank) | G26: (blank) | H26: (blank)
A27: 12 | B27: Jan | C27: 2211 Shelbourne | D27: (blank)
D28: Boormans | E28: GT 1122 | F28: (blank) | G28: (blank) | H28: (blank)
A29: 13 | B29: Feb | C29: 1436 Harrison | D29: (blank)
D30: Boormans | E30: H 6341 | F30: (blank) | G30: (blank) | H30: (blank)
A31: 14 | B31: May-by others | C31: 1149 Rockland | D31: (blank)
D32: Strata Plan Vis 248 | E32: J 9411 | F32: (blank) | G32: (blank) | H32: (blank)
A33: 15 | B33: Jan | C33: 1166 Rockland | D33: (blank)
D34: Freelance | E34: K 6611 | F34: (blank) | G34: (blank) | H34: (blank)
A35: 16 | B35: Dec | C35: 945 McClure | D35: (blank)
D36: Boormans | E36: L 549 | F36: (blank) | G36: (blank) | H36: (blank)
A37: 17 | B37: Jan | C37: 1012 Collinson | D37: (blank)
D38: Hutton | E38: M 1201 | F38: (blank) | G38: (blank) | H38: (blank)
A39: 18 | B39: Feb | C39: 605 Cook | D39: (blank)
D40: Brown Bros | E40: N 506 | F40: (blank) | G40: (blank) | H40: (blank)
A41: 19 | B41: June | C41: 415 Linden | D41: (blank)
D42: Firm Management | E42: R 514 | F42: (blank) | G42: (blank) | H42: (blank)
...

Sheet Monthly- key by address
A1: Street # | B1: Street Name | C1: Site Address | D1: Key code | E1: 123 | F1: Key | G1: code | H1: # keys | I1: Day of Monthly
A2: 890 | B2: Academy Close | C2: =CONCATENATE(A2," ",B2) -> 890 Academy Close | D2: S 098 | E2: 1 | F2: S | G2: 98 | H2: 2 KEYS | I2: 1st Thursday
A3: 28 | B3: Bastion | C3: =CONCATENATE(A3," ",B3) -> 28 Bastion | D3: KEY AT SITE | E3: 0 | F3: KEY AT SITE | H3: n/a | I3: 2nd Wednesday
A4: 31 | B4: Bastion | C4: =CONCATENATE(A4," ",B4) -> 31 Bastion | H4: 2 KEYS | I4: 2nd Wednesday
A5: 1655 | B5: Begbie | C5: =CONCATENATE(A5," ",B5) -> 1655 Begbie | D5: G 5561 | E5: 1 | F5: G | G5: 5561 | H5: 2 KEYS | I5: 1st Thursday
A6: 470 | B6: Belleville | C6: =CONCATENATE(A6," ",B6) -> 470 Belleville | D6: KEY AT SITE | E6: 0 | F6: KEY AT SITE | H6: n/a | I6: 1st Wednesday
A7: 2626 | B7: Blackwood | C7: =CONCATENATE(A7," ",B7) -> 2626 Blackwood | D7: BC 6262 | E7: 3 | F7: BC | G7: 6262 | H7: 2 KEYS | I7: 4th Wednesday
A8: 780 | B8: Blanshard | C8: =CONCATENATE(A8," ",B8) -> 780 Blanshard | D8: B 087 | E8: 1 | F8: B | G8: 87 | H8: 1 KEY, PROXCARD | I8: 1st Wednesday
A9: 810 | B9: Blanshard | C9: =CONCATENATE(A9," ",B9) -> 810 Blanshard | D9: XN 810 | E9: 3 | F9: XN | G9: 810 | H9: 1 KEY, PROXCARD | I9: 1st Wednesday
A10: 1810 | B10: Blanshard | C10: =CONCATENATE(A10," ",B10) -> 1810 Blanshard | D10: RR 0181 | E10: 2 | F10: RR | G10: 181 | H10: 1 KEY, 1 LOCKBOX, PROXCARD | I10: 2nd Wednesday
A11: 1322 | B11: Broad | C11: =CONCATENATE(A11," ",B11) -> 1322 Broad | D11: KEY AT SITE | E11: 0 | F11: KEY AT SITE | H11: n/a | I11: 1st Wednesday
A12: 1221 | B12: Broad | C12: =CONCATENATE(A12," ",B12) -> 1221 Broad | D12: XX 1221 | E12: 2 | F12: XX | G12: 1221 | I12: 2nd Wednesday
A13: 1005 | B13: Broad | C13: =CONCATENATE(A13," ",B13) -> 1005 Broad | D13: K 5001 | E13: 1 | F13: K | G13: 5001 | H13: 3 KEYS | I13: 1st Wednesday
A14: 1205 | B14: Broad/650 View | C14: =CONCATENATE(A14," ",B14) -> 1205 Broad/650 View | D14: BB 5021 | E14: 2 | F14: BB | G14: 5021 | H14: 2 KEYS | I14: 2nd Wednesday
A15: 609 | B15: Broughton | C15: =CONCATENATE(A15," ",B15) -> 609 Broughton | D15: I 906 | E15: 1 | F15: I | G15: 906 | H15: 3 KEYS, FOB | I15: 1st Wednesday
A16: 765-777 | B16: Broughton | C16: =CONCATENATE(A16," ",B16) -> 765-777 Broughton | D16: KEY AT SITE | E16: 0 | F16: KEY AT SITE | H16: n/a | I16: 1st Wednesday
A17: 703 | B17: Broughton | C17: =CONCATENATE(A17," ",B17) -> 703 Broughton | D17: H 307 | E17: 1 | F17: H | G17: 307 | H17: 2 KEYS | I17: 1st Wednesday
A18: 850 | B18: Burdett | C18: =CONCATENATE(A18," ",B18) -> 850 Burdett | D18: A 058 | E18: 1 | F18: A | G18: 58 | H18: 2 KEYS, 2 LOCKBOX KEYS | I18: 1st Wednesday
A19: 2230 | B19: Cadboro Bay | C19: =CONCATENATE(A19," ",B19) -> 2230 Cadboro Bay | D19: D 0322 | E19: 1 | F19: D | G19: 322 | H19: 2 KEYS | I19: 1st Thursday
A20: 1551 | B20: Cedar Hill X Rd | C20: =CONCATENATE(A20," ",B20) -> 1551 Cedar Hill X Rd | D20: KL 1551 | E20: 3 | F20: KL | G20: 1551 | H20: 1 KEY | I20: 4th Wednesday
A21: 1012 | B21: Collinson | C21: =CONCATENATE(A21," ",B21) -> 1012 Collinson | D21: M 2101 | E21: 1 | F21: M | G21: 2101 | H21: 3 KEYS | I21: 1st Thursday
A22: 1947 | B22: Cook | C22: =CONCATENATE(A22," ",B22) -> 1947 Cook | D22: KEY AT SITE | E22: 0 | F22: KEY AT SITE | H22: n/a | I22: 1st Wednesday
A23: 605 | B23: Cook | C23: =CONCATENATE(A23," ",B23) -> 605 Cook | D23: N 506 | E23: 1 | F23: N | G23: 506 | H23: 3 KEYS | I23: 1st Thursday
A24: 230 | B24: Cook | C24: =CONCATENATE(A24," ",B24) -> 230 Cook | D24: Z 032 | E24: 1 | F24: Z | G24: 32 | H24: 1 KEY | I24: 1st Thursday
A25: 209 | B25: Cook | C25: =CONCATENATE(A25," ",B25) -> 209 Cook | D25: Q 902 | E25: 1 | F25: Q | G25: 902 | H25: 1 KEY | I25: 1st Thursday
A26: 722 | B26: Cormorant | C26: =CONCATENATE(A26," ",B26) -> 722 Cormorant | D26: QQ 227 | E26: 2 | F26: QQ | G26: 227 | H26: 2 KEYS | I26: 2nd Wednesday
A27: 770 | B27: Cormorant | C27: =CONCATENATE(A27," ",B27) -> 770 Cormorant | D27: KK 077 | E27: 2 | F27: KK | G27: 77 | H27: 5 KEYS | I27: 2nd Wednesday
A28: 707 | B28: Courtney | C28: =CONCATENATE(A28," ",B28) -> 707 Courtney | D28: A 707 | E28: 1 | F28: A | G28: 707 | H28: 1 KEY, 1 FOB | I28: 1st Wednesday
A29: 3400 | B29: Davidson | C29: =CONCATENATE(A29," ",B29) -> 3400 Davidson | D29: KEY AT SITE | E29: 0 | F29: KEY AT SITE | H29: n/a | I29: 4th Wednesday
A30: 670 | B30: Dallas | C30: =CONCATENATE(A30," ",B30) -> 670 Dallas | D30: O 076 | E30: 1 | F30: O | G30: 76 | H30: 2 KEYS | I30: 1st Thursday
A31: 188 | B31: Douglas | C31: =CONCATENATE(A31," ",B31) -> 188 Douglas | D31: S 881 | E31: 1 | F31: S | G31: 881 | H31: 13 KEYS (May be reduced) | I31: 1st Wednesday
A32: 210 | B32: Douglas | C32: =CONCATENATE(A32," ",B32) -> 210 Douglas | D32: AT 021 | E32: 3 | F32: AT | G32: 21 | H32: 2 KEYS | I32: 1st Thursday
A33: 3045 | B33: Douglas | C33: =CONCATENATE(A33," ",B33) -> 3045 Douglas | D33: GH 5403 | E33: 3 | F33: GH | G33: 5403 | H33: 1KEY | I33: 4th Wednesday
A34: 3301 | B34: Douglas | C34: =CONCATENATE(A34," ",B34) -> 3301 Douglas | D34: HI 1033 | E34: 3 | F34: HI | G34: 1033 | H34: 1 KEY | I34: 4th Wednesday
A35: 713 | B35: Douglas | C35: =CONCATENATE(A35," ",B35) -> 713 Douglas | D35: KEY AT SITE | E35: 0 | F35: KEY AT SITE | H35: n/a | I35: 2nd Wednesday
A36: 1207 | B36: Douglas | C36: =CONCATENATE(A36," ",B36) -> 1207 Douglas | D36: L 7021 | E36: 1 | F36: L | G36: 7021 | H36: 4 KEYS | I36: 1st Wednesday
A37: 350 & 360 | B37: Douglas | C37: =CONCATENATE(A37," ",B37) -> 350 & 360 Douglas | D37: T 053 | E37: 1 | F37: T | G37: 53 | H37: 3 KEYS | I37: 1st Thursday
A38: 1000 - 1012 | B38: Douglas | C38: =CONCATENATE(A38," ",B38) -> 1000 - 1012 Douglas | D38: J 2101 | E38: 1 | F38: J | G38: 2101 | H38: 2 KEYS | I38: 1st Wednesday
A39: 415 | B39: Dunedin | C39: =CONCATENATE(A39," ",B39) -> 415 Dunedin | D39: FG 514 | E39: 3 | F39: FG | G39: 514 | H39: 1 KEY | I39: 4th Wednesday
A40: 1500 | B40: Elford | C40: =CONCATENATE(A40," ",B40) -> 1500 Elford | D40: I 0051 | E40: 1 | F40: I | G40: 51 | H40: 2 KEYS | I40: 1st Thursday
...

Sheet Jan 2026 - Dec 2026
A1: ADDRESS | B1: PROPERTY MANAGEMENT COMPANY | C1: NOTES | D1: BARCODE # | E1: Price/month | F1: Area | G1: start up date | H1: STATUS- (ACTIVE, CANCELLED, ON HOLD) | I1: KEYS | J1: TEST DAY | K1: ANNUAL | L1: 46023 | M1: 46054 | N1: 46082 | O1: 46113 | P1: 46143 | Q1: 46174 | R1: 46204 | S1: 46235 | T1: 46266 | U1: 46296 | V1: 46327 | W1: 46357
A2: #103-4475 Viewmont | B2: Hansbraun | C2: MONTHLY EXT & ELU TESTS - Cancelled in November 2025 | D2: - | E2: 75 | F2: Saanich, BC | G2: 45559 | H2: CANCELLED | I2: No keys | J2: - | K2: May | L2: - | M2: - | N2: - | O2: - | P2: - | Q2: - | R2: - | S2: - | T2: - | U2: - | V2: - | W2: -
A3: 10 Paul Kane/11 Cooperage Place | B3: Proline | D3: 100161 | E3: 55 | F3: Esquimalt, BC | G3: 41730 | H3: ACTIVE | I3: UV 01 | J3: W1-R7 | K3: May | L3: Y | M3: Y | N3: Y | O3: Y | P3: ANNUAL
A4: 1000 Mckenzie Avenue | B4: Starlight/Devon | C4: Increase to $65 after January 2026 | D4: 100229 | E4: 65 | F4: Saanich, BC | G4: 45559 | H4: ACTIVE | I4: M 0001 | J4: W1-R6 | K4: May | L4: Y | M4: Y | N4: Y | O4: X
A5: 1000-1012 Douglas Street | B5: Itziar Management Ltd. (0824606 BC Ltd.) | D5: 100539 | E5: 60 | F5: Victoria, BC | G5: 45589 | H5: ACTIVE | I5: D 2101 | J5: TH2-R15 | K5: June | L5: Y | M5: Y | N5: Y | O5: Y
A6: 1001 Wharf Street | B6: Pastoral Developments Ltd. | D6: 100861 | E6: 55 | F6: Victoria, BC | G6: 43313 | H6: ACTIVE | I6: NA 1001 K2-F1 | J6: TH2-R15 | K6: October | L6: Y | M6: Y | N6: Y | O6: Y
A7: 10016 3rd Street | B7: Cornerstone | D7: 100203 | E7: 50 | F7: Sidney, BC | G7: 44949 | H7: ACTIVE | I7: 358 | J7: F2-R16 | K7: February | L7: Y | M7: Y | N7: ANNUAL | O7: Y
A8: 10017 Avenger Way | B8: Lumberworld Operations Ltd. | C8: Cancelled April 2026 - R16 | D8: - | E8: 75 | F8: Sidney, BC | G8: 45863 | H8: CANCELLED | I8: VG 71001 | J8: - | K8: October | L8: Y | M8: Y | N8: X | O8: Y | P8: - | Q8: - | R8: - | S8: - | T8: - | U8: - | V8: - | W8: -
A9: 1002 Mckenzie Avenue | B9: Starlight/Devon | C9: Increase to $65 after January 2026 | D9: 100966 | E9: 65 | F9: Saanich, BC | G9: 45559 | H9: ACTIVE | I9: M 2001 | J9: W1-R6 | K9: May | L9: Y | M9: Y | N9: Y | O9: X
A10: 1002 Pakington | B10: Proline | D10: 100903 | E10: 50 | F10: Victoria, BC | G10: 44949 | H10: ACTIVE | I10: 146 | J10: TU3-R18 | K10: September | L10: Y | M10: Y | N10: Y | O10: Y
A11: 1002 Wharf Street | B11: Malahat Properties | D11: - | E11: 55 | F11: Victoria, BC | G11: 44174 | H11: ACTIVE | I11: At Reception | J11: TH2-R15 | K11: January | L11: ANNUAL | M11: Y | N11: Y | O11: Y
A12: 10025 Resthaven Drive | B12: Inken Roller c/o Richmond Property Group | D12: 100398 | E12: 50 | F12: Sidney, BC | G12: 44949 | H12: ACTIVE | I12: 349 | J12: F2-R16 | K12: February | L12: Y | M12: ANNUAL | N12: Y | O12: Y
A13: 10030 Resthaven Drive | B13: Raven Property Management Ltd. | D13: 100998 | E13: 75 | F13: Sidney, BC | G13: 44949 | H13: ACTIVE | I13: SC 03001 | J13: F2-R16 | K13: May | L13: Y | M13: Y | N13: Y | O13: Y
A14: 1004 Pemberton Road | B14: Raul Caballero | D14: 100404 | E14: 70 | F14: Victoria, BC | G14: 45161 | H14: ACTIVE | I14: PB 4001 | J14: M1-R1 | K14: December | L14: Y | M14: Y | N14: Y | O14: Y
A15: 1005 & 1009 McKenzie Avenue | B15: Firm Management | C15: Price increase after June 2026 - $60 before that | D15: 100535 | E15: 130 | F15: Saanich, BC | H15: ACTIVE | I15: MN 5001 | J15: TU1-R4 | K15: May | L15: Y | M15: Y | N15: Y | O15: Y | P15: ANNUAL
A16: 1005 Broad Street | B16: Richmond Property Group | D16: 100340 | E16: 55 | F16: Victoria, BC | H16: ACTIVE | I16: K 5001 K4 | J16: TH2-R15 | K16: March | L16: Y | M16: Y | N16: ANNUAL | O16: Y
A17: 1005 Pakington Street | B17: Century 21 Queenswood | D17: 100590 | E17: 50 | F17: Victoria, BC | G17: 44949 | H17: ACTIVE | I17: 171 | J17: TU3-R18 | K17: August | L17: Y | M17: Y | N17: Y | O17: Y
A18: 1005 St. Charles Street | B18: Bross Holdings | D18: 100464 | E18: 55 | F18: Victoria, BC | G18: 45713 | H18: ACTIVE | I18: HC 5001 | J18: TH1-R9 | K18: May | L18: Y | M18: Y | N18: Y | O18: Y
A19: 1006 Fort Street | B19: Colliers | D19: 100619 | E19: 75 | F19: Victoria, BC | G19: 41214 | H19: ACTIVE | I19: ZZ 6001 K3-F1 | J19: M1-R2 | K19: September | L19: Y | M19: Y | N19: Y | O19: Y
A20: 1006 Tolmie Avenue | B20: Century 21 Queenswood | C20: $63.00 credit in QB to be applied to Q2 | D20: 100251 | E20: 60 | F20: Victoria, BC | H20: ACTIVE | I20: 163 | J20: M1-R1 | K20: January | L20: ANNUAL | M20: Y | N20: Y | O20: Y
A21: 1007 Esquimalt Road | B21: Starlight Properties | C21: Increase to $65 after January 2026 | D21: 100595 | E21: 65 | F21: Esquimalt, BC | H21: ACTIVE | I21: LT 7001 | J21: W1-R7 | K21: May | L21: Y | M21: Y | N21: Y | O21: Y
A22: 101 Ontario Street | B22: Proline Property Management | D22: 100210 | E22: 55 | F22: Victoria, BC | G22: 45712 | H22: ACTIVE | I22: TO 101 | J22: W3-R20 | K22: November | L22: Y | M22: Y | N22: X | O22: X
A23: 1010 Mckenzie Avenue | B23: Starlight/Devon | C23: Increase to $65 after January 2026 | D23: 100836 | E23: 65 | F23: Saanich, BC | G23: 45559 | H23: ACTIVE | I23: M 101 | J23: W1-R6 | K23: February | L23: Y | M23: ANNUAL | N23: Y | O23: Y
A24: 1012 Collinson Street | B24: Hutton | D24: 100792 | E24: 55 | F24: Victoria, BC | H24: ACTIVE | I24: M 2101 K3 | J24: TH1-R9 | K24: October | L24: Y | M24: Y | N24: Y | O24: Y
A25: 1013 Vancouver Street | B25: Devon Properties | D25: 100959 | E25: 50 | F25: Victoria, BC | G25: 44949 | H25: ACTIVE | I25: 183 | J25: TH1-R8 | K25: May | L25: Y | M25: Y | N25: Y | O25: Y | P25: ANNUAL
A26: 1015 Kings Road | B26: Darioush Diba | D26: 100272 | E26: 55 | F26: Victoria, BC | G26: 44075 | H26: ACTIVE | I26: KQ 5101 | J26: M1-R3 | K26: June | L26: Y | M26: Y | N26: Y | O26: Y
A27: 10159 Third Street | B27: Realstar Management | D27: 100807 | E27: 55 | F27: Sidney, BC | H27: ACTIVE | I27: 93 | J27: F2-R16 | K27: October | L27: Y | M27: Y | N27: Y | O27: Y
A28: 1017 Queens Avenue | B28: Starlight/Devon | C28: Increase to $65 after January 2026 | D28: 100242 | E28: 65 | F28: Victoria, BC | G28: 44949 | H28: ACTIVE | I28: 111 | J28: M1-R3 | K28: March | L28: Y | M28: Y | N28: ANNUAL | O28: Y
A29: 1019 McClure Street | B29: Strata Plan VIS 308 | D29: 100450 | E29: 65 | F29: Victoria, BC | G29: 45253 | H29: ACTIVE | I29: CL 9101 | J29: TH1-R9 | K29: April | L29: Y | M29: Y | N29: Y | O29: ANNUAL
A30: 1019 Rockland Avenue | B30: Proline | D30: 100558 | E30: 55 | F30: Victoria, BC | G30: 42186 | H30: ACTIVE | I30: ST 9101 K2 | J30: M1-R2 | K30: April | L30: Y | M30: Y | N30: Y | O30: ANNUAL
A31: 1020 Park Boulevard | B31: Pemberton Holmes | D31: 100728 | E31: 50 | F31: Victoria, BC | G31: 44949 | H31: ACTIVE | I31: 92 | J31: TU3-R18 | K31: October | L31: Y | M31: Y | N31: Y | O31: Y
A32: 1020 Pembroke Street | B32: Brown Bros. | D32: 100397 | E32: 55 | F32: Victoria, BC | G32: 42476 | H32: ACTIVE | I32: RT 0201 K2 | J32: M1-R3 | K32: July | L32: Y | M32: Y | N32: Y | O32: Y
A33: 1024 Fairfield Road | B33: Firm Management | D33: 100782 | E33: 55 | F33: Victoria, BC | G33: 41791 | H33: ACTIVE | I33: WT 4201 K3 | J33: TH1-R9 | K33: December | L33: Y | M33: Y | N33: Y | O33: Y
A34: 1025 Johnson Street | B34: Devon Properties | D34: 100923 | E34: 60 | F34: Victoria, BC | G34: 45017 | H34: ACTIVE | I34: JD 5201 K5-F2 | J34: TH1-R8 | K34: January | L34: ANNUAL | M34: Y | N34: Y | O34: Y
A35: 1026 Johnson Street | B35: Firm Management | C35: Cancelled February 2026 - Previously R8 | D35: - | E35: 55 | F35: Victoria, BC | G35: 41821 | H35: CANCELLED | I35: WS 6201 K4-F1 | J35: - | K35: July | L35: Y | M35: - | N35: - | O35: - | P35: - | Q35: - | R35: - | S35: - | T35: - | U35: - | V35: - | W35: -
A36: 1030 Pendergast Street | B36: Starlight/Devon | D36: 100580 | E36: 70 | F36: Victoria, BC | G36: 45192 | H36: ACTIVE | I36: GT 0301 | J36: TU3-R18 | K36: July | L36: Y | M36: Y | N36: Y | O36: Y
A37: 1031 Burdett Avenue | B37: Hutton | C37: cancelled service- Nov 8/24 (tw) | D37: - | E37: 55 | F37: Victoria, BC | G37: 42256 | H37: CANCELLED | I37: BA 1301 K2 | J37: - | K37: December | L37: - | M37: - | N37: - | O37: - | P37: - | Q37: - | R37: - | S37: - | T37: - | U37: - | V37: - | W37: -
A38: 1032 North Park | B38: Pacific Quorum $55 | D38: 100547 | E38: 55 | F38: Victoria, BC | G38: 45039 | H38: ACTIVE | I38: 435 | J38: M1-R3 | K38: March | L38: Y | M38: Y | N38: Y | O38: ANNUAL
A39: 1035 Belmont Avenue | B39: Belmont Properties | D39: 100083 | E39: 55 | F39: Victoria, BC | G39: 45017 | H39: ACTIVE | I39: 445 | J39: TH1-R9 | K39: August | L39: Y | M39: Y | N39: Y | O39: Y
A40: 1035 North Park / 1720 Cook Street | B40: First Service Residential | D40: 100909 | E40: 75 | F40: Victoria, BC | G40: 46016 | H40: ACTIVE | I40: TH 5301 | J40: M1-R3 | K40: April* | L40: Y | M40: Y | N40: Y | O40: ANNUAL
...

Sheet Jan 2024-Dec 2024
A1: ADDRESS | B1: PROPERTY MANAGEMENT COMPANY | C1: NOTES | D1: Price/month | E1: Area | F1: start up date | G1: STATUS- (ACTIVE, CANCELLED, ON HOLD) | H1: KEYS | I1: TEST DAY | J1: ANNUAL | K1: 45292 | L1: 45323 | M1: 45352 | N1: 45383 | O1: 45413 | P1: 45444 | Q1: 45474 | R1: 45505 | S1: 45536 | T1: 45566 | U1: 45597 | V1: 45627
A2: #103-4475 Viewmont | B2: Hansbraun | C2: $75/month MONTHLY EXT & ELU TESTS | D2: 75 | E2: Saanich, BC | F2: 45559 | G2: ACTIVE | H2: NONE | I2: TU1-R4 | J2: May | K2: X | L2: X | M2: X | N2: X | O2: X | P2: X | Q2: X | R2: X | S2: Y | T2: Y | U2: Y | V2: Y
A3: 10 Paul Kane/11 Cooperage Place | B3: Proline | D3: 55 | E3: Esquimalt, BC | F3: 41730 | G3: ACTIVE | H3: UV 01 | I3: W1-R7 | J3: May | K3: Y | L3: Y | M3: Y | N3: Y | O3: ANNUAL | P3: Y | Q3: Y | R3: Y | S3: Y | T3: Y | U3: Y | V3: Y
A4: 1000 Mckenzie Avenue | B4: Devon Properties | D4: 55 | E4: Saanich, BC | F4: 45559 | G4: ACTIVE | H4: M 0001 | I4: W1-R6 | J4: May | K4: X | L4: X | M4: X | N4: X | O4: X | P4: X | Q4: X | R4: X | S4: Y | T4: X | U4: Y | V4: Y
A5: 1000-1012 Douglas Street | B5: Itziar Management Ltd. (0824606 BC Ltd.) | D5: 60 | E5: Victoria, BC | F5: 45589 | G5: ACTIVE | H5: D 2101 | I5: TH2-R15 | J5: June | K5: X | L5: X | M5: X | N5: X | O5: X | P5: X | Q5: X | R5: X | S5: X | T5: X | U5: X | V5: Y
A6: 1001 Wharf Street | B6: Pastoral Developments Ltd. | D6: 55 | E6: Victoria, BC | F6: 43313 | G6: ACTIVE | H6: NA 1001 K2-F1 | I6: TH2-R15 | J6: Oct | K6: Y | L6: Y | M6: Y | N6: Y | O6: Y | P6: Y | Q6: Y | R6: Y | S6: Y | T6: ANNUAL | U6: Y | V6: Y
A7: 10016 3rd Street | B7: Cornerstone | D7: 50 | E7: Sidney, BC | F7: 44949 | G7: ACTIVE | H7: 358 | I7: F2-R16 | J7: Feb | K7: Y | L7: Y | M7: ANNUAL | N7: Y | O7: Y | P7: Y | Q7: Y | R7: Y | S7: Y | T7: Y | U7: Y | V7: Y
A8: 1002 Mckenzie Avenue | B8: Devon Properties | D8: 55 | E8: Saanich, BC | F8: 45559 | G8: ACTIVE | H8: M 0001 | I8: W1-R6 | J8: May | K8: X | L8: X | M8: X | N8: X | O8: X | P8: X | Q8: X | R8: X | S8: Y | T8: X | U8: Y | V8: Y
A9: 1002 Pakington | B9: Devon Properties | D9: 50 | E9: Victoria, BC | F9: 44949 | G9: ACTIVE | H9: 146 | I9: TU3-R18 | J9: Sept* | K9: Y | L9: Y | M9: Y | N9: Y | O9: Y | P9: Y | Q9: Y | R9: Y | S9: ANNUAL | T9: Y | U9: Y | V9: Y
A10: 1002 Wharf Street | B10: Malahat Properties | D10: 55 | E10: Victoria, BC | F10: 44174 | G10: ACTIVE | H10: At Reception | I10: TH2-R15 | J10: Nov | K10: Y | L10: Y | M10: Y | N10: Y | O10: Y | P10: Y | Q10: Y | R10: Y | S10: Y | T10: Y | U10: Y | V10: Y
A11: 10025 Resthaven Drive | B11: Inken Roller c/o Richmond Property Group | D11: 50 | E11: Sidney, BC | F11: 44949 | G11: ACTIVE | H11: 349 | I11: F2-R16 | J11: Feb | K11: Y | L11: Y | M11: Y | N11: Y | O11: Y | P11: X | Q11: Y | R11: Y | S11: Y | T11: Y | U11: Y | V11: Y
A12: 10030 Resthaven Drive | B12: Raven Property Management Ltd. | C12: $75/month (MISC1) | D12: 75 | E12: Sidney, BC | F12: 44228 | G12: ACTIVE | H12: SC 03001 | I12: F2-R16 | J12: May | K12: Y | L12: Y | M12: Y | N12: Y | O12: ANNUAL | P12: X | Q12: Y | R12: Y | S12: Y | T12: Y | U12: Y | V12: Y
A13: 1004 Pemberton Road | B13: Raul Caballero | D13: 70 | E13: Victoria, BC | F13: 45161 | G13: ACTIVE | H13: PB 4001 | I13: M1-R1 | J13: Nov | K13: Y | L13: Y | M13: Y | N13: Y | O13: X | P13: Y | Q13: Y | R13: Y | S13: Y | T13: Y | U13: X | V13: Y
A14: 1005 & 1009 McKenzie Avenue | B14: Firm Management | C14: $60/mth - mthly bell test (B) | D14: 60 | E14: Saanich, BC | G14: ACTIVE | H14: MN 5001 | I14: TU1-R4 | J14: May* | K14: Y | L14: Y | M14: Y | N14: Y | O14: Annual | P14: Y | Q14: Y | R14: Y | S14: Y | T14: Y | U14: Y | V14: Y
A15: 1005 Broad Street | B15: Richmond Property Group | D15: 55 | E15: Victoria, BC | G15: ACTIVE | H15: K 5001 K4 | I15: TH2-R15 | J15: March | K15: Y | L15: Y | M15: ANNUAL | N15: Y | O15: Y | P15: Y | Q15: Y | R15: Y | S15: Y | T15: Y | U15: Y | V15: Y
A16: 1005 Pakington Street | B16: Century 21 Queenswood | D16: 50 | E16: Victoria, BC | F16: 44949 | G16: ACTIVE | H16: 171 | I16: TU3-R18 | J16: August | K16: Y | L16: Y | M16: Y | N16: Y | O16: Y | P16: Y | Q16: Y | R16: Y | S16: X | T16: ANNUAL | U16: Y | V16: Y
A17: 1006 Fort Street | B17: Colliers | C17: $75/month if special service call. PO Required | D17: 75 | E17: Victoria, BC | F17: 41214 | G17: ACTIVE | H17: ZZ 6001 K3-F1 | I17: M1-R2 | J17: September | K17: X | L17: X | M17: X | N17: X | O17: Y | P17: Y | Q17: Y | R17: Y | S17: ANNUAL | T17: Y | U17: Y | V17: Y
A18: 1006 Tolmie Avenue | B18: Century 21 Queenswood | D18: 60 | E18: Victoria, BC | G18: ACTIVE | H18: 163 | I18: M1-R1 | J18: Feb | K18: Y | L18: X & Annual | M18: Y | N18: Y | O18: Y | P18: Y | Q18: Y | R18: Y | S18: Y | T18: Y | U18: X | V18: Y
A19: 1007 Esquimalt Road | B19: Sorenson & Bowers | D19: 50 | E19: Esquimalt, BC | G19: ACTIVE | H19: LT 7001 | I19: W1-R7 | J19: May* | K19: Y | L19: Y | M19: Y | N19: Y | O19: Annual | P19: Y | Q19: Y | R19: Y | S19: Y | T19: Y | U19: Y | V19: Y
A20: 1010 Mckenzie Avenue | B20: Devon Properties | D20: 55 | E20: Saanich, BC | F20: 45559 | G20: ACTIVE | H20: M 0001 | I20: W1-R6 | J20: Febuary | K20: X | L20: X | M20: X | N20: X | O20: X | P20: X | Q20: X | R20: X | S20: Y | T20: X | U20: Y | V20: Y
A21: 1012 Collinson Street | B21: Hutton | D21: 55 | E21: Victoria, BC | G21: ACTIVE | H21: M 2101 K3 | I21: TH1-R9 | J21: Oct | K21: Y | L21: Y | M21: Y | N21: Y | O21: Y | P21: Y | Q21: Y | R21: Y | S21: Y | T21: ANNUAL | U21: Y | V21: Y
A22: 1013 Vancouver Street | B22: Devon Properties | D22: 50 | E22: Victoria, BC | F22: 44949 | G22: ACTIVE | H22: 183 | I22: TH1-R8 | J22: May* | K22: Y | L22: Y | M22: Y | N22: Y | O22: Annual | P22: Y | Q22: Y | R22: Y | S22: Y | T22: Y | U22: Y | V22: Y
A23: 1015 Kings Road | B23: Darioush Diba | D23: 55 | E23: Victoria, BC | F23: 44075 | G23: ACTIVE | H23: KQ 5101 | I23: M1-R3 | J23: June | K23: Y | L23: Y | M23: Y | N23: Y | O23: Y | P23: ANNUAL | Q23: Y | R23: Y | S23: Y | T23: Y | U23: X | V23: Y
A24: 10159 Third Street | B24: Realstar Management | D24: 55 | E24: Sidney, BC | G24: ACTIVE | H24: 93 | I24: F2-R16 | J24: Nov | K24: Y | L24: Y | M24: Y | N24: Y | O24: Y | P24: X | Q24: Y | R24: Y | S24: Y | T24: ANNUAL | U24: Y | V24: Y
A25: 1017 Queens Avenue | B25: Starlight/Devon | C25: Changed to R20 Jan/24 | D25: 50 | E25: Victoria, BC | F25: 44949 | G25: ACTIVE | H25: 111 | I25: M1-R3 | J25: Feb | K25: Y | L25: Y | M25: Y | N25: Y | O25: Y | P25: X | Q25: Y | R25: Y | S25: Y | T25: Y | U25: Y | V25: Y
A26: 1019 McClure Street | B26: Strata Plan VIS 308 | D26: 65 | E26: Victoria, BC | F26: 45253 | G26: ACTIVE | H26: CL 9101 | I26: TH1-R9 | J26: April | K26: Y | L26: Y | M26: Y | N26: ANNUAL | O26: Y | P26: Y | Q26: Y | R26: Y | S26: Y | T26: Y | U26: Y | V26: Y
A27: 1019 Rockland Avenue | B27: Proline | D27: 55 | E27: Victoria, BC | F27: 42186 | G27: ACTIVE | H27: JT 9101 K2 | I27: M1-R2 | J27: Dec | K27: Y | L27: Y | M27: Y | N27: Y | O27: Y | P27: Y | Q27: Y | R27: Y | S27: Y | T27: Y | U27: Y | V27: Y
A28: 1020 Park Boulevard | B28: Pemberton Holmes | D28: 50 | E28: Victoria, BC | F28: 44949 | G28: ACTIVE | H28: 92 | I28: TU3-R18 | J28: Nov | K28: Y | L28: Y | M28: Y | N28: Y | O28: Y | P28: Y | Q28: Y | R28: Y | S28: Y | T28: Y | U28: ANNUAL | V28: Y
A29: 1020 Pembroke Street | B29: Brown Bros. | D29: 55 | E29: Victoria, BC | F29: 42476 | G29: ACTIVE | H29: RT 0201 K2 | I29: M1-R3 | J29: July* | K29: Y | L29: Y | M29: Y | N29: Y | O29: Y | P29: Y | Q29: Y | R29: Y | S29: Y | T29: Y | U29: Y | V29: Y
A30: 1024 Fairfield Road | B30: Firm Management | D30: 55 | E30: Victoria, BC | F30: 41791 | G30: ACTIVE | H30: WT 4201 K3 | I30: TH1-R9 | J30: Dec | K30: Y | L30: Y | M30: Y | N30: Y | O30: Y | P30: Y | Q30: Y | R30: Y | S30: Y | T30: Y | U30: ANNUAL | V30: Y
A31: 1025 Johnson Street | B31: Devon Properties | D31: 60 | E31: Victoria, BC | F31: 45017 | G31: ACTIVE | H31: JD 5201 K5-F2 | I31: TH1-R8 | J31: Dec | K31: Y | L31: Y | M31: Y | N31: Y | O31: Y | P31: Y | Q31: Y | R31: Y | S31: Y | T31: Y | U31: Y | V31: Y
A32: 1026 Johnson Street | B32: Firm Management | D32: 55 | E32: Victoria, BC | F32: 41821 | G32: ACTIVE | H32: WS 6201 K4-F1 | I32: TH1-R8 | J32: July | K32: Y | L32: Y | M32: Y | N32: Y | O32: Y | P32: Y | Q32: Y | R32: Y | S32: Y | T32: Y | U32: Y | V32: Y
A33: 1030 Pendergast Street | B33: Starlight/Devon | D33: 70 | E33: Victoria, BC | F33: 45192 | G33: ACTIVE | H33: GT 0301 | I33: TU3-R18 | J33: July* | K33: Y | L33: Y | M33: Y | N33: Y | O33: X | P33: Y | Q33: ANNUAL | R33: Y | S33: Y | T33: Y | U33: Y | V33: Y
A34: 1031 Burdett Avenue | B34: Hutton | C34: cancelled service- Nov 8/24 (tw) | D34: 55 | E34: Victoria, BC | F34: 42256 | G34: CANCELLED | H34: BA 1301 K2 | I34: - | J34: Dec | K34: Y | L34: Y | M34: Y | N34: Y | O34: Y | P34: Y | Q34: Y | R34: Y | S34: Y | T34: Y | U34: Y | V34: X
A35: 1032 North Park | B35: Pacific Quorum $55 | D35: 55 | E35: Victoria, BC | F35: 45039 | G35: ACTIVE | H35: 435 | I35: M1-R3 | J35: March | K35: Y | L35: Y | M35: Y | N35: ANNUAL | O35: Y | P35: Y | Q35: Y | R35: Y | S35: Y | T35: Y | U35: Y | V35: Y
A36: 1035 Belmont Avenue | B36: Belmont Properties | C36: $47.50/m for 2023 $50/m for 2024 | D36: 50 | E36: Victoria, BC | F36: 45017 | G36: ACTIVE | H36: 445 | I36: TH1-R9 | J36: August* | K36: Y | L36: Y | M36: X | N36: Y | O36: X | P36: Y | Q36: Y | R36: ANNUAL | S36: Y | T36: Y | U36: Y | V36: Y
A37: 1035 Pendergast Street | B37: Starlight/Devon | D37: 70 | E37: Victoria, BC | F37: 45192 | G37: ACTIVE | H37: GT 0301 | I37: TU3-R18 | J37: July* | K37: Y | L37: Y | M37: Y | N37: Y | O37: Y | P37: Y | Q37: ANNUAL | R37: Y | S37: Y | T37: Y | U37: Y | V37: Y
A38: 1036 Stellys Cross Road | B38: Devon Properties | D38: 50 | E38: Brentwood Bay, BC | G38: ACTIVE | H38: 424 | I38: TU2-R12 | J38: Dec | K38: Y | L38: Y | M38: Y | N38: Y | O38: Y | P38: Y | Q38: Y | R38: Y | S38: X | T38: Y | U38: Y | V38: ANNUAL
A39: 104 Dallas Road | B39: Strata #1374 The Dolphins | D39: 55 | E39: Victoria, BC | F39: 43891 | G39: ACTIVE | H39: SP 401 K1-F1 | I39: W3-R20 | J39: August | K39: Y | L39: Y | M39: Y | N39: Y | O39: Y | P39: Y | Q39: Y | R39: ANNUAL | S39: Y | T39: X | U39: X | V39: Y
A40: 1040 Stellys Cross Road | B40: Devon Properties | D40: 50 | E40: Brentwood Bay, BC | G40: ACTIVE | H40: 424 | I40: TU2-R12 | J40: Dec | K40: Y | L40: Y | M40: Y | N40: Y | O40: Y | P40: Y | Q40: Y | R40: Y | S40: X | T40: Y | U40: Y | V40: ANNUAL
...

Sheet Detail1
A1: Details for Count of STATUS- (ACTIVE, CANCELLED, ON HOLD) - STATUS- (ACTIVE, CANCELLED, ON HOLD): ACTIVE
A3: ADDRESS | B3: PROPERTY MANAGEMENT COMPANY | C3: NOTES | D3: Price/month | E3: Area | F3: start up date | G3: STATUS- (ACTIVE, CANCELLED, ON HOLD) | H3: KEYS | I3: TEST DAY | J3: ANNUAL | K3: Jan-25 | L3: Feb-25 | M3: Mar-25 | N3: Apr-25 | O3: May-25 | P3: Jun-25 | Q3: Jul-25 | R3: Aug-25 | S3: Sep-25 | T3: Oct-25 | U3: Nov-25 | V3: Dec-25
A4: #103-4475 Viewmont | B4: Hansbraun | C4: MONTHLY EXT & ELU TESTS | D4: 75 | E4: Saanich, BC | F4: 45559 | G4: ACTIVE | H4: NONE | I4: TU1-R4 | J4: May | K4: Y | L4: Y | M4: Y | N4: Y | O4: ANNUAL | P4: Y | Q4: Y | R4: Y
A5: 10 Paul Kane/11 Cooperage Place | B5: Proline | D5: 55 | E5: Esquimalt, BC | F5: 41730 | G5: ACTIVE | H5: UV 01 | I5: W1-R7 | J5: May | K5: Y | L5: X | M5: Y | N5: Y | O5: ANNUAL | P5: X | Q5: Y | R5: Y
A6: 1000 Mckenzie Avenue | B6: Starlight/Devon | D6: 55 | E6: Saanich, BC | F6: 45559 | G6: ACTIVE | H6: M 0001 | I6: W1-R6 | J6: May | K6: Y | L6: Y | M6: Y | N6: Y | O6: Y | P6: ANNUAL | Q6: X | R6: X
A7: 1000-1012 Douglas Street | B7: Itziar Management Ltd. (0824606 BC Ltd.) | D7: 60 | E7: Victoria, BC | F7: 45589 | G7: ACTIVE | H7: D 2101 | I7: TH2-R15 | J7: June | K7: Y | L7: Y | M7: Y | N7: Y | O7: Y | P7: Y | Q7: Y
A8: 1001 Wharf Street | B8: Pastoral Developments Ltd. | D8: 55 | E8: Victoria, BC | F8: 43313 | G8: ACTIVE | H8: NA 1001 K2-F1 | I8: TH2-R15 | J8: October | K8: Y | L8: Y | M8: Y | N8: Y | O8: Y | P8: Y | Q8: Y
A9: 10016 3rd Street | B9: Cornerstone | D9: 50 | E9: Sidney, BC | F9: 44949 | G9: ACTIVE | H9: 358 | I9: F2-R16 | J9: February | K9: Y | L9: Y | M9: ANNUAL | N9: Y | O9: Y | P9: Y | Q9: Y
A10: 10017 Avenger Way | B10: Lumberworld Operations Ltd. | D10: 75 | E10: Sidney, BC | F10: 45863 | G10: ACTIVE | H10: VG 71001 | I10: F2-R16 | J10: October | K10: X | L10: X | M10: X | N10: X | O10: X | P10: X | Q10: X
A11: 1002 Mckenzie Avenue | B11: Starlight/Devon | D11: 55 | E11: Saanich, BC | F11: 45559 | G11: ACTIVE | H11: M 0001 | I11: W1-R6 | J11: May | K11: Y | L11: Y | M11: Y | N11: Y | O11: Y | P11: ANNUAL | Q11: X | R11: Y
A12: 1002 Pakington | B12: Devon Properties | D12: 50 | E12: Victoria, BC | F12: 44949 | G12: ACTIVE | H12: 146 | I12: TU3-R18 | J12: September | K12: Y | L12: Y | M12: Y | N12: Y | O12: Y | P12: Y | Q12: Y | S12: ANNUAL
A13: 1002 Wharf Street | B13: Malahat Properties | D13: 55 | E13: Victoria, BC | F13: 44174 | G13: ACTIVE | H13: At Reception | I13: TH2-R15 | J13: January | K13: Y | L13: ANNUAL | M13: Y | N13: Y | O13: Y | P13: Y | Q13: Y
A14: 10025 Resthaven Drive | B14: Inken Roller c/o Richmond Property Group | D14: 50 | E14: Sidney, BC | F14: 44949 | G14: ACTIVE | H14: 349 | I14: F2-R16 | J14: February | K14: Y | L14: ANNUAL | M14: X | N14: Y | O14: Y | P14: Y | Q14: Y
A15: 10030 Resthaven Drive | B15: Raven Property Management Ltd. | D15: 75 | E15: Sidney, BC | F15: 44228 | G15: ACTIVE | H15: SC 03001 | I15: F2-R16 | J15: May | K15: Y | L15: Y | M15: Y | N15: Y | O15: Y | P15: ANNUAL | Q15: Y
A16: 1004 Pemberton Road | B16: Raul Caballero | D16: 70 | E16: Victoria, BC | F16: 45161 | G16: ACTIVE | H16: PB 4001 | I16: M1-R1 | J16: December | K16: ANNUAL | L16: Y | M16: Y | N16: Y | O16: Y | P16: Y | Q16: Y | R16: Y
A17: 1005 & 1009 McKenzie Avenue | B17: Firm Management | D17: 60 | E17: Saanich, BC | G17: ACTIVE | H17: MN 5001 | I17: TU1-R4 | J17: May | K17: X | L17: X | M17: X | N17: X | O17: X | P17: ANNUAL | Q17: Y | R17: Y
A18: 1005 Broad Street | B18: Richmond Property Group | D18: 55 | E18: Victoria, BC | G18: ACTIVE | H18: K 5001 K4 | I18: TH2-R15 | J18: March | K18: Y | L18: Y | M18: ANNUAL | N18: Y | O18: Y | P18: Y | Q18: Y
A19: 1005 Pakington Street | B19: Century 21 Queenswood | D19: 50 | E19: Victoria, BC | F19: 44949 | G19: ACTIVE | H19: 171 | I19: TU3-R18 | J19: August | K19: Y | L19: Y | M19: Y | N19: Y | O19: Y | P19: Y | Q19: Y
A20: 1005 St. Charles Street | B20: Bross Holdings | D20: 55 | E20: Victoria, BC | F20: 45713 | G20: ACTIVE | H20: HC 5001 | I20: TH1-R9 | J20: May | K20: X | L20: Y | M20: Y | N20: Y | O20: Y | P20: ANNUAL | Q20: Y | R20: Y
A21: 1006 Fort Street | B21: Colliers | D21: 75 | E21: Victoria, BC | F21: 41214 | G21: ACTIVE | H21: ZZ 6001 K3-F1 | I21: M1-R2 | J21: September | K21: Y | L21: Y | M21: Y | N21: Y | O21: Y | P21: Y | Q21: Y | R21: ANNUAL
A22: 1006 Tolmie Avenue | B22: Century 21 Queenswood | D22: 60 | E22: Victoria, BC | G22: ACTIVE | H22: 163 | I22: M1-R1 | J22: January | K22: Y | L22: ANNUAL | M22: Y | N22: Y | O22: Y | P22: Y | Q22: Y | R22: Y
A23: 1007 Esquimalt Road | B23: Starlight Properties | D23: 50 | E23: Esquimalt, BC | G23: ACTIVE | H23: LT 7001 | I23: W1-R7 | J23: May | K23: Y | L23: Y | M23: Y | N23: Y | O23: ANNUAL | P23: X | Q23: Y | R23: Y
A24: 101 Ontario Street | B24: Proline Property Management | D24: 55 | E24: Victoria, BC | F24: 45712 | G24: ACTIVE | H24: OT 101 | I24: W3-R20 | J24: November | K24: X | L24: Y | M24: Y | N24: Y | O24: Y | P24: Y | Q24: Y
A25: 1010 Mckenzie Avenue | B25: Starlight/Devon | D25: 55 | E25: Saanich, BC | F25: 45559 | G25: ACTIVE | H25: M 0001 | I25: W1-R6 | J25: February | K25: Y | L25: ANNUAL | M25: Y | N25: Y | O25: Y | P25: X | Q25: X | R25: Y
A26: 1012 Collinson Street | B26: Hutton | D26: 55 | E26: Victoria, BC | G26: ACTIVE | H26: M 2101 K3 | I26: TH1-R9 | J26: October | K26: Y | L26: Y | M26: Y | N26: Y | O26: Y | P26: Y | Q26: Y | R26: Y
A27: 1013 Vancouver Street | B27: Devon Properties | D27: 50 | E27: Victoria, BC | F27: 44949 | G27: ACTIVE | H27: 183 | I27: TH1-R8 | J27: May | K27: Y | L27: Y | M27: Y | N27: Y | O27: X | P27: Y | Q27: Y | R27: Y
A28: 1015 Kings Road | B28: Darioush Diba | D28: 55 | E28: Victoria, BC | F28: 44075 | G28: ACTIVE | H28: KQ 5101 | I28: M1-R3 | J28: June | K28: Y | L28: Y | M28: Y | N28: Y | O28: Y | P28: ANNUAL | Q28: Y | R28: Y
A29: 10159 Third Street | B29: Realstar Management | D29: 55 | E29: Sidney, BC | G29: ACTIVE | H29: 93 | I29: F2-R16 | J29: November | K29: Y | L29: Y | M29: Y | N29: Y | O29: Y | P29: Y | Q29: Y
A30: 1017 Queens Avenue | B30: Starlight/Devon | D30: 50 | E30: Victoria, BC | F30: 44949 | G30: ACTIVE | H30: 111 | I30: M1-R3 | J30: March | K30: Y | L30: Y | M30: Y | N30: ANNUAL | O30: Y | P30: Y | Q30: Y | R30: Y
A31: 1019 McClure Street | B31: Strata Plan VIS 308 | D31: 65 | E31: Victoria, BC | F31: 45253 | G31: ACTIVE | H31: CL 9101 | I31: TH1-R9 | J31: April | K31: Y | L31: Y | M31: Y | N31: ANNUAL | O31: Y | P31: Y | Q31: Y | R31: Y
A32: 1019 Rockland Avenue | B32: Proline | D32: 55 | E32: Victoria, BC | F32: 42186 | G32: ACTIVE | H32: ST 9101 K2 | I32: M1-R2 | J32: December | K32: Y | L32: Y | M32: Y | N32: ANNUAL | O32: Y | P32: Y | Q32: Y | R32: Y
A33: 1020 Park Boulevard | B33: Pemberton Holmes | D33: 50 | E33: Victoria, BC | F33: 44949 | G33: ACTIVE | H33: 92 | I33: TU3-R18 | J33: November | K33: Y | L33: Y | M33: Y | N33: Y | O33: Y | P33: Y | Q33: Y
A34: 1020 Pembroke Street | B34: Brown Bros. | D34: 55 | E34: Victoria, BC | F34: 42476 | G34: ACTIVE | H34: RT 0201 K2 | I34: M1-R3 | J34: July | K34: Y | L34: Y | M34: Y | N34: Y | O34: Y | P34: Y | Q34: ANNUAL | R34: Y
A35: 1024 Fairfield Road | B35: Firm Management | D35: 55 | E35: Victoria, BC | F35: 41791 | G35: ACTIVE | H35: WT 4201 K3 | I35: TH1-R9 | J35: December | K35: Y | L35: Y | M35: Y | N35: Y | O35: ANNUAL | P35: Y | Q35: Y | R35: Y
A36: 1025 Johnson Street | B36: Devon Properties | D36: 60 | E36: Victoria, BC | F36: 45017 | G36: ACTIVE | H36: JD 5201 K5-F2 | I36: TH1-R8 | J36: January | K36: ANNUAL | L36: Y | M36: Y | N36: Y | O36: Y | P36: Y | Q36: Y | R36: Y
A37: 1026 Johnson Street | B37: Firm Management | D37: 55 | E37: Victoria, BC | F37: 41821 | G37: ACTIVE | H37: WS 6201 K4-F1 | I37: TH1-R8 | J37: July | K37: Y | L37: Y | M37: Y | N37: Y | O37: Y | P37: Y | Q37: Y | R37: Y
A38: 1030 Pendergast Street | B38: Starlight/Devon | D38: 70 | E38: Victoria, BC | F38: 45192 | G38: ACTIVE | H38: GT 0301 | I38: TU3-R18 | J38: July | K38: Y | L38: Y | M38: Y | N38: Y | O38: Y | P38: Y | Q38: ANNUAL
A39: 9993 Fourth Street | B39: Complete Residential | D39: 50 | E39: Sidney, BC | G39: ACTIVE | H39: 417 | I39: F1-R10 | J39: April | K39: Y | L39: Y | M39: Y | N39: ANNUAL | O39: Y | P39: Y | Q39: Y | R39: Y
A40: 1032 North Park | B40: Pacific Quorum $55 | D40: 55 | E40: Victoria, BC | F40: 45039 | G40: ACTIVE | H40: 435 | I40: M1-R3 | J40: March | K40: X | L40: Y | M40: X | N40: ANNUAL | O40: X | P40: X | Q40: X | R40: Y
A41: 1035 Belmont Avenue | B41: Belmont Properties | D41: 55 | E41: Victoria, BC | F41: 45017 | G41: ACTIVE | H41: 445 | I41: TH1-R9 | J41: August | K41: Y | L41: Y | M41: Y | N41: Y | O41: Y | P41: Y | Q41: Y | R41: Y | S41: ANNUAL
...

Sheet Detail3
A1: Details for Count of X - ANNUAL: January, STATUS- (ACTIVE, CANCELLED, ON HOLD): ACTIVE
A3: ADDRESS | B3: PROPERTY MANAGEMENT COMPANY | C3: NOTES | D3: Price/month | E3: Area | F3: start up date | G3: STATUS- (ACTIVE, CANCELLED, ON HOLD) | H3: KEYS | I3: TEST DAY | J3: ANNUAL | K3: Jan-25 | L3: Feb-25 | M3: Mar-25 | N3: Apr-25 | O3: May-25 | P3: Jun-25 | Q3: Jul-25 | R3: Aug-25 | S3: Sep-25 | T3: Oct-25 | U3: Nov-25 | V3: Dec-25
A4: 9972 Third Street | B4: Highstreet Fourth Street (2023) LP | D4: 50 | E4: Sidney, BC | F4: 44949 | G4: ACTIVE | H4: No Key | I4: F1-R10 | J4: January | K4: Y | L4: ANNUAL | M4: Y | N4: Y | O4: Y | P4: Y | Q4: Y | R4: Y
A5: 984 Mckenzie Avenue | B5: Starlight/Devon | D5: 55 | E5: Saanich, BC | F5: 45559 | G5: ACTIVE | H5: ZM 489 | I5: W1-R6 | J5: January | K5: Y | L5: Y | M5: Y | N5: Y | O5: Y | P5: X | Q5: X | R5: Y
A6: 906 Southgate Street | B6: South Island Property Mgmt (was Strata Plan Vis 742 | D6: 55 | E6: Victoria, BC | F6: 41456 | G6: ACTIVE | H6: HT 609 K2 | I6: TU3-R18 | J6: January | K6: ANNUAL | L6: Y | M6: Y | N6: Y | O6: Y | P6: Y | Q6: Y
A7: 890 Academy Close | B7: Breakwater Realty | C7: PO Required $55/month | D7: 55 | E7: Victoria, BC | G7: ACTIVE | H7: S 098 K2 | I7: TU3-R18 | J7: January | K7: ANNUAL | L7: Y | M7: Y | N7: Y | O7: Y | P7: Y | Q7: Y
A8: 838 Fort Street | B8: Minzar Holdings Ltd | D8: 55 | E8: Victoria, BC | F8: 43604 | G8: ACTIVE | H8: E 838 K2-F1 | I8: M1-R2 | J8: January | K8: Y | L8: ANNUAL | M8: Y | N8: Y | O8: Y | P8: Y | Q8: Y | R8: Y
A9: 815 Queens Avenue | B9: Devon Properties | D9: 50 | E9: Victoria, BC | F9: 44949 | G9: ACTIVE | H9: 337 | I9: M1-R3 | J9: January | K9: Y | L9: ANNUAL | M9: Y | N9: Y | O9: Y | P9: Y | Q9: Y | R9: Y
A10: 780 Kings Road | B10: Chek TV | D10: 55 | E10: Victoria, BC | F10: 44986 | G10: ACTIVE | H10: CN 087 | I10: M2-R11 | J10: January | K10: X | L10: Y | M10: Y | N10: X | O10: X | P10: Y | Q10: Y | R10: Y
A11: 747 Fort Street | B11: Associated Building Credits Ltd. c/o Breakwater Realty Inc. | D11: 65 | E11: Victoria, BC | F11: 45253 | G11: ACTIVE | H11: RF 747 | I11: TH2-R15 | J11: January | K11: Y | L11: Y | M11: Y | N11: Y | O11: Y | P11: ANNUAL | Q11: Y
A12: 720 Vancouver Street | B12: Century 21 Queenswood | D12: 50 | E12: Victoria, BC | F12: 44949 | G12: ACTIVE | H12: 69 | I12: TH1-R9 | J12: January | K12: Y & ANNUAL | L12: Y | M12: Y | N12: Y | O12: Y | P12: Y | Q12: Y | R12: Y
A13: 1002 Wharf Street | B13: Malahat Properties | D13: 55 | E13: Victoria, BC | F13: 44174 | G13: ACTIVE | H13: At Reception | I13: TH2-R15 | J13: January | K13: Y | L13: ANNUAL | M13: Y | N13: Y | O13: Y | P13: Y | Q13: Y
A14: 709-715 Yates Street | B14: Churchill on Yates GP C/O Daniel Belanger | D14: 55 | E14: Victoria, BC | F14: 42614 | G14: ACTIVE | H14: R 527 K6-F1 | I14: TH2-R15 | J14: January | K14: ANNUAL | L14: Y | M14: Y | N14: Y | O14: Y | P14: Y | Q14: Y
A15: 651 Jolly Place | B15: Cornerstone | D15: 55 | E15: Victoria, BC | F15: 44094 | G15: ACTIVE | H15: JP 156 | I15: TU1-R4 | J15: January | K15: Y | L15: ANNUAL | M15: Y | N15: Y | O15: Y | P15: X | Q15: Y | R15: Y
A16: 545 Johnson Street | B16: Devon Properties | D16: 50 | E16: Victoria, BC | F16: 44949 | G16: ACTIVE | H16: 401 | I16: TH3-R21 | J16: January | K16: Y | L16: Y | M16: Y | N16: Y | O16: Y | P16: Y | Q16: Y
A17: 539-545 Fisgard Street | B17: Servissio | D17: 70 | E17: Victoria, BC | F17: 45017 | G17: ACTIVE | H17: FA 935 | I17: TH3-R21 | J17: January | K17: ANNUAL | L17: Y | M17: Y | N17: Y | O17: Y | P17: Y | Q17: Y
A18: 520 Rithet Street | B18: Newport Property management | D18: 50 | E18: Victoria, BC | G18: ACTIVE | H18: 403 | I18: M1-R2 | J18: January | K18: ANNUAL | L18: Y | M18: Y | N18: Y | O18: Y | P18: Y | Q18: Y | R18: Y
A19: 500 Rithet Street | B19: Belmont Properties | C19: $50/m for 2024 | D19: 60 | E19: Victoria, BC | F19: 45017 | G19: ACTIVE | H19: 443 (Ring 3) | I19: W3-R20 | J19: January | K19: Y | L19: Y | M19: Y | N19: Y | O19: Y | P19: Y | Q19: Y
A20: 493 Burnside Road East | B20: Devon Properties | D20: 55 | E20: Victoria, BC | F20: 45748 | G20: ACTIVE | H20: SB 394 | I20: TU3-R19 | J20: January | K20: X | L20: X | M20: X | N20: Y | O20: Y | P20: Y | Q20: Y
A21: 3962 Cedar Hill Road | B21: Firm Management | D21: 50 | E21: Saanich, BC | F21: 45283 | G21: ACTIVE | H21: HD 8593 | I21: TU1-R4 | J21: January | K21: ANNUAL | L21: Y | M21: Y | N21: Y | O21: Y | P21: Y | Q21: Y | R21: Y
A22: 1006 Tolmie Avenue | B22: Century 21 Queenswood | D22: 60 | E22: Victoria, BC | G22: ACTIVE | H22: 163 | I22: M1-R1 | J22: January | K22: Y | L22: ANNUAL | M22: Y | N22: Y | O22: Y | P22: Y | Q22: Y | R22: Y
A23: 3958 Cedar Hill Road | B23: Firm Management | D23: 50 | E23: Saanich, BC | F23: 45283 | G23: ACTIVE | H23: HD 8593 | I23: TU1-R4 | J23: January | K23: Y | L23: ANNUAL | M23: Y | N23: Y | O23: Y | P23: Y | Q23: Y | R23: Y
A24: 3005 Cook Street | B24: Kiwanis Village Society | D24: 65 | E24: Victoria, BC | F24: 45713 | G24: ACTIVE | H24: CK 5003 | I24: W1-R6 | J24: January | K24: ANNUAL | L24: Y | M24: Y | N24: Y | O24: Y | P24: Y | Q24: Y | R24: Y
A25: 2771 Jacklin Road | B25: Groupe Denux | D25: 50 | E25: Langford, BC | G25: ACTIVE | H25: 418 | I25: TU1-R5 | J25: January | K25: Y | L25: ANNUAL | M25: Y | N25: Y | O25: Y | P25: Y | Q25: Y | R25: Y
A26: 2421 Sidney Avenue | B26: Complete Residential | D26: 50 | E26: Sidney, BC | F26: 45047 | G26: ACTIVE | H26: 416 | I26: F1-R10 | J26: January | K26: Y | L26: ANNUAL | M26: Y | N26: Y | O26: Y | P26: Y | Q26: Y | R26: Y
A27: 235 Michigan Street | B27: Brown Brothers Property Management | C27: First 3 months are free | D27: 75 | E27: Victoria, BC | F27: 45863 | G27: ACTIVE | H27: CG 532 | I27: W3-R20 | J27: January | K27: X | L27: X | M27: X | N27: X | O27: X | P27: X | Q27: Y
A28: 2243 Beacon Avenue | B28: Mary Winspear Centre | D28: 50 | E28: Sidney, BC | F28: 44949 | G28: ACTIVE | H28: No Key | I28: F1-R10 | J28: January | K28: Y | L28: ANNUAL | M28: X | N28: X | O28: Y | P28: Y | Q28: Y | R28: Y
A29: 2210 Cadboro Bay Road | B29: Brown Bros. | D29: 65 | E29: Oak Bay, BC | F29: 45406 | G29: ACTIVE | H29: DA 0122 | I29: W2-R14 | J29: January | K29: ANNUAL | L29: Y | M29: Y | N29: Y | O29: Y | P29: Y | Q29: Y
A30: 2129 Florence Street | B30: Devon Properties | D30: 50 | E30: Victoria, BC | F30: 44949 | G30: ACTIVE | H30: 305 | I30: W2-R14 | J30: January | K30: Y | L30: Y | M30: ANNUAL | N30: Y | O30: Y | P30: Y | Q30: Y
A31: 2065 Oak Bay Avenue | B31: Brown Bros. | D31: 55 | E31: Oak Bay, BC | G31: ACTIVE | H31: 428 | I31: TU2-R13 | J31: January | K31: Y | L31: Y | M31: Y | N31: Y | O31: ANNUAL | P31: Y | Q31: Y | R31: Y
A32: 2030 Malaview Drive | B32: Slegg L.P. | D32: 50 | E32: Sidney, BC | F32: 44949 | G32: ACTIVE | H32: No Key | I32: F2-R16 | J32: January | K32: Y | L32: ANNUAL | M32: Y | N32: Y | O32: Y | P32: Y | Q32: Y
A33: 1964 Fort Street | B33: Hutton | D33: 50 | E33: Victoria, BC | F33: 44949 | G33: ACTIVE | H33: 181 | I33: W2-R14 | J33: January | K33: ANNUAL | L33: Y | M33: Y | N33: Y | O33: Y | P33: Y | Q33: Y
A34: 1885 Forest Park Drive | B34: Panorama Leisure | D34: 55 | E34: North Saanich, BC | G34: ACTIVE | H34: No Key | I34: F2-R16 | J34: January | K34: Y | L34: ANNUAL | M34: Y | N34: X | O34: X | P34: X | Q34: X
A35: 1581 Hillside Avenue | B35: Brown Brothers Property Management | D35: 55 | E35: Victoria, BC | G35: ACTIVE | H35: W 1851 K2 | I35: W1-R6 | J35: January | K35: Y & ANNUAL | L35: Y | M35: Y | N35: Y | O35: Y | P35: Y | Q35: Y | R35: Y
A36: 1025 Johnson Street | B36: Devon Properties | D36: 60 | E36: Victoria, BC | F36: 45017 | G36: ACTIVE | H36: JD 5201 K5-F2 | I36: TH1-R8 | J36: January | K36: ANNUAL | L36: Y | M36: Y | N36: Y | O36: Y | P36: Y | Q36: Y | R36: Y
A37: 1485 Fort Street | B37: Peter Hejjas | D37: 65 | E37: Victoria, BC | G37: ACTIVE | H37: 138 | I37: M1-R1 | J37: January | K37: Y | L37: Y | M37: Y | N37: ANNUAL | O37: Y | P37: Y | Q37: Y | R37: Y
A38: 1461 Blanshard Street | B38: Congregation Emanu-el | D38: 60 | E38: Victoria, BC | F38: 45283 | G38: ACTIVE | H38: LD 1641 | I38: TH1-R8 | J38: January | K38: Y & ANNUAL | L38: Y | M38: Y | N38: Y | O38: Y | P38: Y | Q38: X | R38: X
A39: 1445 Fort Street | B39: Brown Bros. | D39: 50 | E39: Victoria, BC | F39: 44949 | G39: ACTIVE | H39: 141 | I39: TH1-R8 | J39: January | K39: ANNUAL | L39: Y | M39: Y | N39: Y | O39: Y | P39: Y | Q39: Y | R39: Y
A40: 1369 Mitchell Street | B40: Oak Bay United Church | D40: 55 | E40: Oak Bay, BC | F40: 44501 | G40: ACTIVE | H40: UC 9631 K2 | I40: TU2-R13 | J40: January | K40: ANNUAL | L40: Y | M40: Y | N40: Y | O40: Y | P40: Y | Q40: Y | R40: Y
A41: 1250 Wharf Street | B41: Servissio Property Services Ltd. | D41: 55 | E41: Victoria, BC | F41: 44167 | G41: ACTIVE | H41: TG 0521 K4 | I41: TH3-R21 | J41: January | K41: Y & ANNUAL | L41: Y | M41: Y | N41: Y | O41: X | P41: Y | Q41: Y
...

Sheet Annual Charts
B2: Row Labels | C2: Count of STATUS- (ACTIVE, CANCELLED, ON HOLD) | F2: STATUS- (ACTIVE, CANCELLED, ON HOLD) | G2: ACTIVE
B3: ACTIVE | C3: 583
B4: CANCELLED | C4: 19 | F4: Row Labels | G4: Count of ANNUAL
B5: ON HOLD | C5: 3 | F5: M1-R1 | G5: 31
B6: WAITING KEYS | C6: 6 | F6: M1-R2 | G6: 29
B7: (blank) | F7: M1-R3 | G7: 29
B8: Grand Total | C8: 611 | F8: TU1-R4 | G8: 27
F9: TU1-R5 | G9: 36
F10: W1-R6 | G10: 34
F11: W1-R7 | G11: 28
B12: STATUS- (ACTIVE, CANCELLED, ON HOLD) | C12: ACTIVE | F12: TH1-R8 | G12: 27
F13: TH1-R9 | G13: 30
B14: Row Labels | C14: Count of ANNUAL | F14: F1-R10 | G14: 28
B15: January | C15: 44 | D15: =GETPIVOTDATA("ANNUAL",$B$14,"ANNUAL","January")/GETPIVOTDATA("ANNUAL",$B$14) -> 0.075471698 | F15: M2-R11 | G15: 12
B16: February | C16: 40 | D16: =GETPIVOTDATA("ANNUAL",$B$14,"ANNUAL","February")/GETPIVOTDATA("ANNUAL",$B$14) -> 0.068610635 | F16: TU2-R12 | G16: 29
B17: March | C17: 62 | D17: =GETPIVOTDATA("ANNUAL",$B$14,"ANNUAL","March")/GETPIVOTDATA("ANNUAL",$B$14) -> 0.10634648 | F17: TU2-R13 | G17: 21
B18: April | C18: 44 | D18: =GETPIVOTDATA("ANNUAL",$B$14,"ANNUAL","April")/GETPIVOTDATA("ANNUAL",$B$14) -> 0.075471698 | F18: W2-R14 | G18: 32
B19: May | C19: 65 | D19: =GETPIVOTDATA("ANNUAL",$B$14,"ANNUAL","May")/GETPIVOTDATA("ANNUAL",$B$14) -> 0.11149228 | F19: TH2-R15 | G19: 29
B20: June | C20: 45 | D20: =GETPIVOTDATA("ANNUAL",$B$14,"ANNUAL","June")/GETPIVOTDATA("ANNUAL",$B$14) -> 0.077186964 | F20: F2-R16 | G20: 27
B21: July | C21: 63 | D21: =GETPIVOTDATA("ANNUAL",$B$14,"ANNUAL","July")/GETPIVOTDATA("ANNUAL",$B$14) -> 0.10806175 | F21: M3-R17 | G21: 13
B22: August | C22: 38 | D22: =GETPIVOTDATA("ANNUAL",$B$14,"ANNUAL","August")/GETPIVOTDATA("ANNUAL",$B$14) -> 0.065180103 | F22: TU3-R18 | G22: 27
B23: September | C23: 63 | D23: =GETPIVOTDATA("ANNUAL",$B$14,"ANNUAL","September")/GETPIVOTDATA("ANNUAL",$B$14) -> 0.10806175 | F23: TU3-R19 | G23: 23
B24: October | C24: 43 | D24: =GETPIVOTDATA("ANNUAL",$B$14,"ANNUAL","October")/GETPIVOTDATA("ANNUAL",$B$14) -> 0.073756432 | F24: W3-R20 | G24: 32
B25: November | C25: 44 | D25: =GETPIVOTDATA("ANNUAL",$B$14,"ANNUAL","November")/GETPIVOTDATA("ANNUAL",$B$14) -> 0.075471698 | F25: TH3-R21 | G25: 24
B26: December | C26: 30 | D26: =GETPIVOTDATA("ANNUAL",$B$14,"ANNUAL","December")/GETPIVOTDATA("ANNUAL",$B$14) -> 0.051457976 | F26: W2-R22 | G26: 15
C27: 1 | D27: =GETPIVOTDATA("ANNUAL",$B$14,"ANNUAL"," ")/GETPIVOTDATA("ANNUAL",$B$14) -> 0.0017152659 | F27: Grand Total | G27: 583
B28: T.O | C28: 1 | D28: =GETPIVOTDATA("ANNUAL",$B$14,"ANNUAL","T.O")/GETPIVOTDATA("ANNUAL",$B$14) -> 0.0017152659
B29: Grand Total | C29: 583

Sheet 2026 Completion Chart
A2: Cantec Monthlies - Completion Chart
A3: Route # | B3: # Of Sites | C3: Average Finish Time (3:30-4pm) | D3: Locked Routes | E3: Total # of Skipped (Per Route) | F3: January | I3: February | L3: March | O3: April | R3: May | U3: June | X3: July | AA3: August | AD3: September | AG3: October | AJ3: November | AM3: December
F4: Finish time | G4: Completed? | H4: # Skipped | I4: Finish time | J4: Completed? | K4: # Skipped | L4: Finish time | M4: Completed? | N4: # Skipped | O4: Finish time | P4: Completed? | Q4: # Skipped | R4: Finish time | S4: Completed? | T4: # Skipped | U4: Finish time | V4: Completed? | W4: # Skipped | X4: Finish time | Y4: Completed? | Z4: # Skipped | AA4: Finish time | AB4: Completed? | AC4: # Skipped | AD4: Finish time | AE4: Completed? | AF4: # Skipped | AG4: Finish time | AH4: Completed? | AI4: # Skipped | AJ4: Finish time | AK4: Completed? | AL4: # Skipped | AM4: Finish time | AN4: Completed? | AO4: # Skipped
A5: R1 | B5: =COUNTIF('Jan 2026 - Dec 2026'!J1:J743, "M1-R1") -> 34 | C5: =AVERAGE(F5,I5,L5,O5,R5,U5,X5,AA5,AD5) -> 0.65138889 | D5: Locked | E5: =SUM(H5,K5,N5,Q5,T5,W5,Z5,AC5,AF5,AI5,AL5,AO5) -> 12 | F5: 0.64652778 | G5: Y | H5: 3 | I5: 0.64861111 | J5: Y | K5: 2 | L5: 0.65625 | M5: Y | N5: 5 | O5: 0.65416667 | P5: Y | Q5: 2
A6: R2 | B6: =COUNTIF('Jan 2026 - Dec 2026'!J1:J744, "M1-R2") -> 31 | C6: =AVERAGE(F6,I6,L6,O6,R6,U6,X6,AA6,AD6,AG6,AJ6,PJ6) -> 0.63194444 | D6: Locked | E6: =SUM(H6,K6,N6,Q6,T6,W6,Z6,AC6,AF6,AI6,AL6,AO6) -> 18 | F6: 0.60277778 | G6: Y | H6: 3 | I6: 0.64583333 | J6: Y | K6: 2 | L6: 0.62152778 | M6: Y | N6: 7 | O6: 0.65763889 | P6: Y | Q6: 6
A7: R3 | B7: =COUNTIF('Jan 2026 - Dec 2026'!J1:J745, "M1-R3") -> 33 | C7: =AVERAGE(F7,I7,L7,O7,R7,U7,X7,AA7,AD7,AG7,AJ7,PJ7) -> 0.66284722 | D7: Locked | E7: =SUM(H7,K7,N7,Q7,T7,W7,Z7,AC7,AF7,AI7,AL7,AO7) -> 14 | F7: 0.67708333 | G7: Y | H7: 2 | I7: 0.67361111 | J7: Y | K7: 3 | L7: 0.66597222 | M7: Y | N7: 4 | O7: 0.63472222 | P7: Y | Q7: 5
A8: R4 | B8: =COUNTIF('Jan 2026 - Dec 2026'!J1:J746, "TU1-R4") -> 16 | C8: =AVERAGE(F8,I8,L8,O8,R8,U8,X8,AA8,AD8,AG8,AJ8,PJ8) -> 0.57309028 | E8: =SUM(H8,K8,N8,Q8,T8,W8,Z8,AC8,AF8,AI8,AL8,AO8) -> 4 | F8: 0.59930556 | G8: Y | H8: 1 | I8: 0.5625 | J8: Y | K8: 1 | L8: 0.52569444 | M8: Y | N8: 0 | O8: 0.60486111 | P8: Y | Q8: 2
A9: R5 | B9: =COUNTIF('Jan 2026 - Dec 2026'!J1:J731, "TU1-R5") -> 26 | C9: =AVERAGE(F9,I9,L9,O9,R9,U9,X9,AA9,AD9,AG9,AJ9,PJ9) -> 0.65763889 | E9: =SUM(H9,K9,N9,Q9,T9,W9,Z9,AC9,AF9,AI9,AL9,AO9) -> 1 | F9: 0.64930556 | G9: Y | H9: 0 | I9: 0.65138889 | J9: Y | K9: 0 | L9: 0.67013889 | M9: Y | N9: 1 | O9: 0.65972222 | P9: Y | Q9: 0
A10: R6 | B10: =COUNTIF('Jan 2026 - Dec 2026'!J1:J732, "W1-R6") -> 33 | C10: =AVERAGE(F10,I10,L10,O10,R10,U10,X10,AA10,AD10,AG10,AJ10,PJ10) -> 0.64704861 | D10: Locked | E10: =SUM(H10,K10,N10,Q10,T10,W10,Z10,AC10,AF10,AI10,AL10,AO10) -> 20 | F10: 0.65347222 | G10: Y | H10: 3 | I10: 0.62638889 | J10: Y | K10: 7 | L10: 0.63541667 | M10: Y | N10: 2 | O10: 0.67291667 | P10: X | Q10: 8
A11: R7 | B11: =COUNTIF('Jan 2026 - Dec 2026'!J2:J733, "w1-r7") -> 30 | C11: =AVERAGE(F11,I11,L11,O11,R11,U11,X11,AA11,AD11,AG11,AJ11,PJ11) -> 0.67708333 | D11: Locked | E11: =SUM(H11,K11,N11,Q11,T11,W11,Z11,AC11,AF11,AI11,AL11,AO11) -> 11 | F11: 0.67222222 | G11: Y | H11: 3 | I11: 0.70416667 | J11: Y | K11: 0 | L11: 0.65972222 | M11: Y | N11: 4 | O11: 0.67222222 | P11: Y | Q11: 4
A12: R8 | B12: =COUNTIF('Jan 2026 - Dec 2026'!J1:J734, "TH1-R8") -> 27 | C12: =AVERAGE(F12,I12,L12,O12,R12,U12,X12,AA12,AD12,AG12,AJ12,PJ12) -> 0.64444444 | D12: Locked | E12: =SUM(H12,K12,N12,Q12,T12,W12,Z12,AC12,AF12,AI12,AL12,AO12) -> 10 | F12: 0.65416667 | G12: Y | H12: 3 | I12: 0.66666667 | J12: Y | K12: 0 | L12: 0.59027778 | M12: Y | N12: 2 | O12: 0.66666667 | P12: X | Q12: 5
A13: R9 | B13: =COUNTIF('Jan 2026 - Dec 2026'!J1:J735, "TH1-R9") -> 32 | C13: =AVERAGE(F13,I13,L13,O13,R13,U13,X13,AA13,AD13,AG13,AJ13,PJ13) -> 0.67447917 | D13: Locked | E13: =SUM(H13,K13,N13,Q13,T13,W13,Z13,AC13,AF13,AI13,AL13,AO13) -> 9 | F13: 0.67361111 | G13: Y | H13: 2 | I13: 0.66111111 | J13: Y | K13: 2 | L13: 0.68263889 | M13: Y | N13: 0 | O13: 0.68055556 | P13: Y | Q13: 5
A14: R10 | B14: =COUNTIF('Jan 2026 - Dec 2026'!J1:J736, "F1-R10") -> 29 | C14: =AVERAGE(F14,I14,L14,O14,R14,U14,X14,AA14,AD14,AG14,AJ14,PJ14) -> 0.64392361 | E14: =SUM(H14,K14,N14,Q14,T14,W14,Z14,AC14,AF14,AI14,AL14,AO14) -> 15 | F14: 0.66944444 | G14: Y | H14: 2 | I14: 0.62152778 | J14: Y | K14: 5 | L14: 0.61111111 | M14: Y | N14: 4 | O14: 0.67361111 | P14: Y | Q14: 4
A15: R11 | B15: =COUNTIF('Jan 2026 - Dec 2026'!J1:J731, "M2-R11") -> 12 | C15: =AVERAGE(F15,I15,L15,O15,R15,U15,X15,AA15,AD15,AG15,AJ15,PJ15) -> 0.64114583 | D15: Locked | E15: =SUM(H15,K15,N15,Q15,T15,W15,Z15,AC15,AF15,AI15,AL15,AO15) -> 7 | F15: 0.65625 | G15: Y | H15: 1 | I15: 0.64236111 | J15: Y | K15: 1 | L15: 0.64236111 | M15: Y | N15: 3 | O15: 0.62361111 | P15: Y | Q15: 2
A16: R12 | B16: =COUNTIF('Jan 2026 - Dec 2026'!J1:J731, "TU2-R12") -> 30 | C16: =AVERAGE(F16,I16,L16,O16,R16,U16,X16,AA16,AD16,AG16,AJ16,PJ16) -> 0.65902778 | D16: Locked | E16: =SUM(H16,K16,N16,Q16,T16,W16,Z16,AC16,AF16,AI16,AL16,AO16) -> 13 | F16: 0.65347222 | G16: Y | H16: 3 | I16: 0.64513889 | J16: X | K16: 6 | L16: 0.67291667 | M16: Y | N16: 1 | O16: 0.66458333 | P16: Y | Q16: 3
